[2023-03-17T11:01:56.265+0000] {taskinstance.py:1083} INFO - Dependencies all met for <TaskInstance: LocalIngestionDag.ingest scheduled__2021-01-02T06:00:00+00:00 [queued]>
[2023-03-17T11:01:56.274+0000] {taskinstance.py:1083} INFO - Dependencies all met for <TaskInstance: LocalIngestionDag.ingest scheduled__2021-01-02T06:00:00+00:00 [queued]>
[2023-03-17T11:01:56.274+0000] {taskinstance.py:1279} INFO - 
--------------------------------------------------------------------------------
[2023-03-17T11:01:56.274+0000] {taskinstance.py:1280} INFO - Starting attempt 2 of 2
[2023-03-17T11:01:56.274+0000] {taskinstance.py:1281} INFO - 
--------------------------------------------------------------------------------
[2023-03-17T11:01:56.286+0000] {taskinstance.py:1300} INFO - Executing <Task(PythonOperator): ingest> on 2021-01-02 06:00:00+00:00
[2023-03-17T11:01:56.290+0000] {standard_task_runner.py:55} INFO - Started process 3885 to run task
[2023-03-17T11:01:56.292+0000] {standard_task_runner.py:82} INFO - Running: ['***', 'tasks', 'run', 'LocalIngestionDag', 'ingest', 'scheduled__2021-01-02T06:00:00+00:00', '--job-id', '1791', '--raw', '--subdir', 'DAGS_FOLDER/data_ingestion_local.py', '--cfg-path', '/tmp/tmpivibj_u2']
[2023-03-17T11:01:56.293+0000] {standard_task_runner.py:83} INFO - Job 1791: Subtask ingest
[2023-03-17T11:01:56.304+0000] {warnings.py:110} WARNING - /home/***/.local/lib/python3.7/site-packages/***/settings.py:249: DeprecationWarning: The sql_alchemy_conn option in [core] has been moved to the sql_alchemy_conn option in [database] - the old setting has been used, but please update your config.
  SQL_ALCHEMY_CONN = conf.get("database", "SQL_ALCHEMY_CONN")

[2023-03-17T11:01:56.324+0000] {warnings.py:110} WARNING - /home/***/.local/lib/python3.7/site-packages/***/utils/sqlalchemy.py:124: DeprecationWarning: The sql_alchemy_conn option in [core] has been moved to the sql_alchemy_conn option in [database] - the old setting has been used, but please update your config.
  return not conf.get("database", "sql_alchemy_conn").startswith("mssql")

[2023-03-17T11:01:56.354+0000] {task_command.py:388} INFO - Running <TaskInstance: LocalIngestionDag.ingest scheduled__2021-01-02T06:00:00+00:00 [running]> on host 846854af4045
[2023-03-17T11:01:56.390+0000] {warnings.py:110} WARNING - /home/***/.local/lib/python3.7/site-packages/***/utils/context.py:205: AirflowContextDeprecationWarning: Accessing 'execution_date' from the template is deprecated and will be removed in a future version. Please use 'data_interval_start' or 'logical_date' instead.
  warnings.warn(_create_deprecation_warning(key, self._deprecation_replacements[key]))

[2023-03-17T11:01:56.423+0000] {taskinstance.py:1509} INFO - Exporting the following env vars:
AIRFLOW_CTX_DAG_OWNER=***
AIRFLOW_CTX_DAG_ID=LocalIngestionDag
AIRFLOW_CTX_TASK_ID=ingest
AIRFLOW_CTX_EXECUTION_DATE=2021-01-02T06:00:00+00:00
AIRFLOW_CTX_TRY_NUMBER=2
AIRFLOW_CTX_DAG_RUN_ID=scheduled__2021-01-02T06:00:00+00:00
[2023-03-17T11:01:56.424+0000] {logging_mixin.py:137} INFO - yellow_tax_2021_01 /opt/***/output_2021-01.csv 2021-01-02T06:00:00+00:00
[2023-03-17T11:01:56.428+0000] {ingestion_script.py:12} INFO - connected to ny_taxi
[2023-03-17T11:01:56.429+0000] {taskinstance.py:1768} ERROR - Task failed with exception
Traceback (most recent call last):
  File "/home/airflow/.local/lib/python3.7/site-packages/airflow/operators/python.py", line 175, in execute
    return_value = self.execute_callable()
  File "/home/airflow/.local/lib/python3.7/site-packages/airflow/operators/python.py", line 192, in execute_callable
    return self.python_callable(*self.op_args, **self.op_kwargs)
  File "/opt/airflow/dags/ingestion_script.py", line 14, in ingest_callable
    df_iter = pd.read_csv(csv_file, iterator=True, chunksize=100000)
  File "/home/airflow/.local/lib/python3.7/site-packages/pandas/util/_decorators.py", line 311, in wrapper
    return func(*args, **kwargs)
  File "/home/airflow/.local/lib/python3.7/site-packages/pandas/io/parsers/readers.py", line 586, in read_csv
    return _read(filepath_or_buffer, kwds)
  File "/home/airflow/.local/lib/python3.7/site-packages/pandas/io/parsers/readers.py", line 482, in _read
    parser = TextFileReader(filepath_or_buffer, **kwds)
  File "/home/airflow/.local/lib/python3.7/site-packages/pandas/io/parsers/readers.py", line 811, in __init__
    self._engine = self._make_engine(self.engine)
  File "/home/airflow/.local/lib/python3.7/site-packages/pandas/io/parsers/readers.py", line 1040, in _make_engine
    return mapping[engine](self.f, **self.options)  # type: ignore[call-arg]
  File "/home/airflow/.local/lib/python3.7/site-packages/pandas/io/parsers/c_parser_wrapper.py", line 51, in __init__
    self._open_handles(src, kwds)
  File "/home/airflow/.local/lib/python3.7/site-packages/pandas/io/parsers/base_parser.py", line 229, in _open_handles
    errors=kwds.get("encoding_errors", "strict"),
  File "/home/airflow/.local/lib/python3.7/site-packages/pandas/io/common.py", line 707, in get_handle
    newline="",
FileNotFoundError: [Errno 2] No such file or directory: '/opt/airflow/output_2021-01.csv'
[2023-03-17T11:01:56.437+0000] {taskinstance.py:1323} INFO - Marking task as FAILED. dag_id=LocalIngestionDag, task_id=ingest, execution_date=20210102T060000, start_date=20230317T110156, end_date=20230317T110156
[2023-03-17T11:01:56.445+0000] {standard_task_runner.py:105} ERROR - Failed to execute job 1791 for task ingest ([Errno 2] No such file or directory: '/opt/airflow/output_2021-01.csv'; 3885)
[2023-03-17T11:01:56.464+0000] {local_task_job.py:208} INFO - Task exited with return code 1
[2023-03-17T11:01:56.477+0000] {taskinstance.py:2578} INFO - 0 downstream tasks scheduled from follow-on schedule check
