[2023-03-23T10:24:45.112+0000] {taskinstance.py:1083} INFO - Dependencies all met for <TaskInstance: gcs_2_bq_dag.move_fhv_tripdata_external_table scheduled__2023-03-22T00:00:00+00:00 [queued]>
[2023-03-23T10:24:45.121+0000] {taskinstance.py:1083} INFO - Dependencies all met for <TaskInstance: gcs_2_bq_dag.move_fhv_tripdata_external_table scheduled__2023-03-22T00:00:00+00:00 [queued]>
[2023-03-23T10:24:45.122+0000] {taskinstance.py:1279} INFO - 
--------------------------------------------------------------------------------
[2023-03-23T10:24:45.122+0000] {taskinstance.py:1280} INFO - Starting attempt 1 of 2
[2023-03-23T10:24:45.122+0000] {taskinstance.py:1281} INFO - 
--------------------------------------------------------------------------------
[2023-03-23T10:24:45.132+0000] {taskinstance.py:1300} INFO - Executing <Task(BigQueryCreateExternalTableOperator): move_fhv_tripdata_external_table> on 2023-03-22 00:00:00+00:00
[2023-03-23T10:24:45.137+0000] {standard_task_runner.py:55} INFO - Started process 565 to run task
[2023-03-23T10:24:45.139+0000] {standard_task_runner.py:82} INFO - Running: ['***', 'tasks', 'run', 'gcs_2_bq_dag', 'move_fhv_tripdata_external_table', 'scheduled__2023-03-22T00:00:00+00:00', '--job-id', '1943', '--raw', '--subdir', 'DAGS_FOLDER/transfer_gcp_to_bq.py', '--cfg-path', '/tmp/tmp20e0cpvq']
[2023-03-23T10:24:45.141+0000] {standard_task_runner.py:83} INFO - Job 1943: Subtask move_fhv_tripdata_external_table
[2023-03-23T10:24:45.150+0000] {warnings.py:110} WARNING - /home/***/.local/lib/python3.7/site-packages/***/settings.py:249: DeprecationWarning: The sql_alchemy_conn option in [core] has been moved to the sql_alchemy_conn option in [database] - the old setting has been used, but please update your config.
  SQL_ALCHEMY_CONN = conf.get("database", "SQL_ALCHEMY_CONN")

[2023-03-23T10:24:45.170+0000] {warnings.py:110} WARNING - /home/***/.local/lib/python3.7/site-packages/***/utils/sqlalchemy.py:124: DeprecationWarning: The sql_alchemy_conn option in [core] has been moved to the sql_alchemy_conn option in [database] - the old setting has been used, but please update your config.
  return not conf.get("database", "sql_alchemy_conn").startswith("mssql")

[2023-03-23T10:24:45.201+0000] {task_command.py:388} INFO - Running <TaskInstance: gcs_2_bq_dag.move_fhv_tripdata_external_table scheduled__2023-03-22T00:00:00+00:00 [running]> on host 4b3eeaf199d3
[2023-03-23T10:24:45.253+0000] {taskinstance.py:1509} INFO - Exporting the following env vars:
AIRFLOW_CTX_DAG_OWNER=***
AIRFLOW_CTX_DAG_ID=gcs_2_bq_dag
AIRFLOW_CTX_TASK_ID=move_fhv_tripdata_external_table
AIRFLOW_CTX_EXECUTION_DATE=2023-03-22T00:00:00+00:00
AIRFLOW_CTX_TRY_NUMBER=1
AIRFLOW_CTX_DAG_RUN_ID=scheduled__2023-03-22T00:00:00+00:00
[2023-03-23T10:24:45.254+0000] {crypto.py:83} WARNING - empty cryptography key - values will not be stored encrypted.
[2023-03-23T10:24:45.254+0000] {base.py:73} INFO - Using connection ID 'google_cloud_default' for task execution.
[2023-03-23T10:24:45.833+0000] {taskinstance.py:1768} ERROR - Task failed with exception
Traceback (most recent call last):
  File "/home/airflow/.local/lib/python3.7/site-packages/airflow/providers/google/cloud/operators/bigquery.py", line 1629, in execute
    table_resource=self.table_resource,
  File "/home/airflow/.local/lib/python3.7/site-packages/airflow/providers/google/common/hooks/base_google.py", line 468, in inner_wrapper
    return func(self, *args, **kwargs)
  File "/home/airflow/.local/lib/python3.7/site-packages/airflow/providers/google/cloud/hooks/bigquery.py", line 407, in create_empty_table
    table=table, exists_ok=exists_ok, retry=retry
  File "/home/airflow/.local/lib/python3.7/site-packages/google/cloud/bigquery/client.py", line 755, in create_table
    timeout=timeout,
  File "/home/airflow/.local/lib/python3.7/site-packages/google/cloud/bigquery/client.py", line 782, in _call_api
    return call()
  File "/home/airflow/.local/lib/python3.7/site-packages/google/api_core/retry.py", line 288, in retry_wrapped_func
    on_error=on_error,
  File "/home/airflow/.local/lib/python3.7/site-packages/google/api_core/retry.py", line 190, in retry_target
    return target()
  File "/home/airflow/.local/lib/python3.7/site-packages/google/cloud/_http/__init__.py", line 494, in api_request
    raise exceptions.from_http_response(response)
google.api_core.exceptions.BadRequest: 400 POST https://bigquery.googleapis.com/bigquery/v2/projects/winged-vigil-379810/datasets/trips_data_all/tables?prettyPrint=false: Error while reading table: fhv_tripdata_external_table, error message: Failed to expand table fhv_tripdata_external_table with file pattern gs://dtc_data_lake_winged-vigil-379810/fhv/*: matched no files. File: gs://dtc_data_lake_winged-vigil-379810/fhv/*
[2023-03-23T10:24:45.841+0000] {taskinstance.py:1323} INFO - Marking task as UP_FOR_RETRY. dag_id=gcs_2_bq_dag, task_id=move_fhv_tripdata_external_table, execution_date=20230322T000000, start_date=20230323T102445, end_date=20230323T102445
[2023-03-23T10:24:45.854+0000] {standard_task_runner.py:105} ERROR - Failed to execute job 1943 for task move_fhv_tripdata_external_table (400 POST https://bigquery.googleapis.com/bigquery/v2/projects/winged-vigil-379810/datasets/trips_data_all/tables?prettyPrint=false: Error while reading table: fhv_tripdata_external_table, error message: Failed to expand table fhv_tripdata_external_table with file pattern gs://dtc_data_lake_winged-vigil-379810/fhv/*: matched no files. File: gs://dtc_data_lake_winged-vigil-379810/fhv/*; 565)
[2023-03-23T10:24:45.873+0000] {local_task_job.py:208} INFO - Task exited with return code 1
[2023-03-23T10:24:45.894+0000] {taskinstance.py:2578} INFO - 0 downstream tasks scheduled from follow-on schedule check
