[2023-03-18T12:58:47.988+0000] {taskinstance.py:1083} INFO - Dependencies all met for <TaskInstance: data_ingestion_gcs_dag.local_to_gcs manual__2023-03-18T12:49:41.702896+00:00 [queued]>
[2023-03-18T12:58:47.997+0000] {taskinstance.py:1083} INFO - Dependencies all met for <TaskInstance: data_ingestion_gcs_dag.local_to_gcs manual__2023-03-18T12:49:41.702896+00:00 [queued]>
[2023-03-18T12:58:47.998+0000] {taskinstance.py:1279} INFO - 
--------------------------------------------------------------------------------
[2023-03-18T12:58:47.998+0000] {taskinstance.py:1280} INFO - Starting attempt 2 of 2
[2023-03-18T12:58:47.998+0000] {taskinstance.py:1281} INFO - 
--------------------------------------------------------------------------------
[2023-03-18T12:58:48.015+0000] {taskinstance.py:1300} INFO - Executing <Task(PythonOperator): local_to_gcs> on 2023-03-18 12:49:41.702896+00:00
[2023-03-18T12:58:48.024+0000] {standard_task_runner.py:55} INFO - Started process 145 to run task
[2023-03-18T12:58:48.027+0000] {standard_task_runner.py:82} INFO - Running: ['***', 'tasks', 'run', 'data_ingestion_gcs_dag', 'local_to_gcs', 'manual__2023-03-18T12:49:41.702896+00:00', '--job-id', '1828', '--raw', '--subdir', 'DAGS_FOLDER/ingestion_script_gcp.py', '--cfg-path', '/tmp/tmp7ggzpnzk']
[2023-03-18T12:58:48.028+0000] {standard_task_runner.py:83} INFO - Job 1828: Subtask local_to_gcs
[2023-03-18T12:58:48.041+0000] {warnings.py:110} WARNING - /home/***/.local/lib/python3.7/site-packages/***/settings.py:249: DeprecationWarning: The sql_alchemy_conn option in [core] has been moved to the sql_alchemy_conn option in [database] - the old setting has been used, but please update your config.
  SQL_ALCHEMY_CONN = conf.get("database", "SQL_ALCHEMY_CONN")

[2023-03-18T12:58:48.088+0000] {task_command.py:388} INFO - Running <TaskInstance: data_ingestion_gcs_dag.local_to_gcs manual__2023-03-18T12:49:41.702896+00:00 [running]> on host 723d2829f2a8
[2023-03-18T12:58:48.176+0000] {taskinstance.py:1509} INFO - Exporting the following env vars:
AIRFLOW_CTX_DAG_OWNER=***
AIRFLOW_CTX_DAG_ID=data_ingestion_gcs_dag
AIRFLOW_CTX_TASK_ID=local_to_gcs
AIRFLOW_CTX_EXECUTION_DATE=2023-03-18T12:49:41.702896+00:00
AIRFLOW_CTX_TRY_NUMBER=2
AIRFLOW_CTX_DAG_RUN_ID=manual__2023-03-18T12:49:41.702896+00:00
[2023-03-18T12:58:48.177+0000] {taskinstance.py:1768} ERROR - Task failed with exception
Traceback (most recent call last):
  File "/home/airflow/.local/lib/python3.7/site-packages/airflow/operators/python.py", line 175, in execute
    return_value = self.execute_callable()
  File "/home/airflow/.local/lib/python3.7/site-packages/airflow/operators/python.py", line 192, in execute_callable
    return self.python_callable(*self.op_args, **self.op_kwargs)
  File "/opt/airflow/dags/ingestion_script_gcp.py", line 46, in upload_to_gcs
    client = storage.Client()
  File "/home/airflow/.local/lib/python3.7/site-packages/google/cloud/storage/client.py", line 128, in __init__
    _http=_http,
  File "/home/airflow/.local/lib/python3.7/site-packages/google/cloud/client/__init__.py", line 320, in __init__
    _ClientProjectMixin.__init__(self, project=project, credentials=credentials)
  File "/home/airflow/.local/lib/python3.7/site-packages/google/cloud/client/__init__.py", line 268, in __init__
    project = self._determine_default(project)
  File "/home/airflow/.local/lib/python3.7/site-packages/google/cloud/client/__init__.py", line 287, in _determine_default
    return _determine_default_project(project)
  File "/home/airflow/.local/lib/python3.7/site-packages/google/cloud/_helpers/__init__.py", line 152, in _determine_default_project
    _, project = google.auth.default()
  File "/home/airflow/.local/lib/python3.7/site-packages/google/auth/_default.py", line 459, in default
    credentials, project_id = checker()
  File "/home/airflow/.local/lib/python3.7/site-packages/google/auth/_default.py", line 222, in _get_explicit_environ_credentials
    os.environ[environment_vars.CREDENTIALS]
  File "/home/airflow/.local/lib/python3.7/site-packages/google/auth/_default.py", line 108, in load_credentials_from_file
    "File {} was not found.".format(filename)
google.auth.exceptions.DefaultCredentialsError: File /.gc/credentials/google_credentials.json was not found.
[2023-03-18T12:58:48.187+0000] {taskinstance.py:1323} INFO - Marking task as FAILED. dag_id=data_ingestion_gcs_dag, task_id=local_to_gcs, execution_date=20230318T124941, start_date=20230318T125847, end_date=20230318T125848
[2023-03-18T12:58:48.198+0000] {standard_task_runner.py:105} ERROR - Failed to execute job 1828 for task local_to_gcs (File /.gc/credentials/google_credentials.json was not found.; 145)
[2023-03-18T12:58:48.238+0000] {local_task_job.py:208} INFO - Task exited with return code 1
[2023-03-18T12:58:48.260+0000] {taskinstance.py:2578} INFO - 0 downstream tasks scheduled from follow-on schedule check
