[2023-03-18T14:13:49.751+0000] {taskinstance.py:1084} INFO - Dependencies all met for dep_context=non-requeueable deps ti=<TaskInstance: data_ingestion_gcs_dag.local_to_gcs manual__2023-03-18T14:13:20.847225+00:00 [queued]>
[2023-03-18T14:13:49.760+0000] {taskinstance.py:1084} INFO - Dependencies all met for dep_context=requeueable deps ti=<TaskInstance: data_ingestion_gcs_dag.local_to_gcs manual__2023-03-18T14:13:20.847225+00:00 [queued]>
[2023-03-18T14:13:49.760+0000] {taskinstance.py:1282} INFO - 
--------------------------------------------------------------------------------
[2023-03-18T14:13:49.760+0000] {taskinstance.py:1283} INFO - Starting attempt 1 of 1
[2023-03-18T14:13:49.760+0000] {taskinstance.py:1284} INFO - 
--------------------------------------------------------------------------------
[2023-03-18T14:13:49.769+0000] {taskinstance.py:1303} INFO - Executing <Task(PythonOperator): local_to_gcs> on 2023-03-18 14:13:20.847225+00:00
[2023-03-18T14:13:49.776+0000] {standard_task_runner.py:55} INFO - Started process 219 to run task
[2023-03-18T14:13:49.778+0000] {standard_task_runner.py:82} INFO - Running: ['***', 'tasks', 'run', 'data_ingestion_gcs_dag', 'local_to_gcs', 'manual__2023-03-18T14:13:20.847225+00:00', '--job-id', '1858', '--raw', '--subdir', 'DAGS_FOLDER/ingestion_script_gcp.py', '--cfg-path', '/tmp/tmphuagi5m1']
[2023-03-18T14:13:49.779+0000] {standard_task_runner.py:83} INFO - Job 1858: Subtask local_to_gcs
[2023-03-18T14:13:49.790+0000] {warnings.py:110} WARNING - /home/***/.local/lib/python3.7/site-packages/***/settings.py:250: DeprecationWarning: The sql_alchemy_conn option in [core] has been moved to the sql_alchemy_conn option in [database] - the old setting has been used, but please update your config.
  SQL_ALCHEMY_CONN = conf.get("database", "SQL_ALCHEMY_CONN")

[2023-03-18T14:13:49.826+0000] {task_command.py:388} INFO - Running <TaskInstance: data_ingestion_gcs_dag.local_to_gcs manual__2023-03-18T14:13:20.847225+00:00 [running]> on host d0995c198d04
[2023-03-18T14:13:49.882+0000] {taskinstance.py:1511} INFO - Exporting the following env vars:
AIRFLOW_CTX_DAG_OWNER=***
AIRFLOW_CTX_DAG_ID=data_ingestion_gcs_dag
AIRFLOW_CTX_TASK_ID=local_to_gcs
AIRFLOW_CTX_EXECUTION_DATE=2023-03-18T14:13:20.847225+00:00
AIRFLOW_CTX_TRY_NUMBER=1
AIRFLOW_CTX_DAG_RUN_ID=manual__2023-03-18T14:13:20.847225+00:00
[2023-03-18T14:13:49.883+0000] {taskinstance.py:1775} ERROR - Task failed with exception
Traceback (most recent call last):
  File "/home/airflow/.local/lib/python3.7/site-packages/airflow/operators/python.py", line 175, in execute
    return_value = self.execute_callable()
  File "/home/airflow/.local/lib/python3.7/site-packages/airflow/operators/python.py", line 192, in execute_callable
    return self.python_callable(*self.op_args, **self.op_kwargs)
  File "/opt/airflow/dags/ingestion_script_gcp.py", line 46, in upload_to_gcs
    client = storage.Client()
  File "/home/airflow/.local/lib/python3.7/site-packages/google/cloud/storage/client.py", line 128, in __init__
    _http=_http,
  File "/home/airflow/.local/lib/python3.7/site-packages/google/cloud/client/__init__.py", line 320, in __init__
    _ClientProjectMixin.__init__(self, project=project, credentials=credentials)
  File "/home/airflow/.local/lib/python3.7/site-packages/google/cloud/client/__init__.py", line 268, in __init__
    project = self._determine_default(project)
  File "/home/airflow/.local/lib/python3.7/site-packages/google/cloud/client/__init__.py", line 287, in _determine_default
    return _determine_default_project(project)
  File "/home/airflow/.local/lib/python3.7/site-packages/google/cloud/_helpers/__init__.py", line 152, in _determine_default_project
    _, project = google.auth.default()
  File "/home/airflow/.local/lib/python3.7/site-packages/google/auth/_default.py", line 459, in default
    credentials, project_id = checker()
  File "/home/airflow/.local/lib/python3.7/site-packages/google/auth/_default.py", line 222, in _get_explicit_environ_credentials
    os.environ[environment_vars.CREDENTIALS]
  File "/home/airflow/.local/lib/python3.7/site-packages/google/auth/_default.py", line 108, in load_credentials_from_file
    "File {} was not found.".format(filename)
google.auth.exceptions.DefaultCredentialsError: File /opt/***/google_credentials.json was not found.
[2023-03-18T14:13:49.893+0000] {taskinstance.py:1326} INFO - Marking task as FAILED. dag_id=data_ingestion_gcs_dag, task_id=local_to_gcs, execution_date=20230318T141320, start_date=20230318T141349, end_date=20230318T141349
[2023-03-18T14:13:49.905+0000] {standard_task_runner.py:105} ERROR - Failed to execute job 1858 for task local_to_gcs (File /opt/***/google_credentials.json was not found.; 219)
[2023-03-18T14:13:49.950+0000] {local_task_job.py:212} INFO - Task exited with return code 1
[2023-03-18T14:13:49.962+0000] {taskinstance.py:2585} INFO - 0 downstream tasks scheduled from follow-on schedule check
